<?xml version="1.0"?>
<robot xmlns:xacro="http://www.ros.org/wiki/xacro" >

    <xacro:include filename="inertial_macros.xacro"/>

    <material name="white">
    <color rgba="1 1 1 1"/>
</material>

<material name="orange">
    <color rgba="1 0.3 0.1 1"/>
</material>

<material name="blue">
    <color rgba="0.2 0.2 1 1"/>
</material>

<material name="black">
    <color rgba="0 0 0 1"/>
</material>

<!-- BASE -->

<link name="base_link">
</link>

<!-- CHASSIS -->

<joint name="chassis_joint" type="fixed">
    <parent link="base_link"/>
    <child link="chassis_link"/>
    <origin xyz="-0.15 0 0"/>
</joint>

<link name="chassis_link">

    <visual>
        <origin xyz="0.15 0 0.05" rpy="0 0 0"/>
        <geometry>
            <box size="0.3 0.2 0.15"/>
        </geometry>
        <material name="white"/>
    </visual>

    <collision>
        <origin xyz="0.15 0 0.05" rpy="0 0 0"/>
        <geometry>
            <box size="0.3 0.2 0.15"/>
        </geometry>
    </collision>

    <xacro:inertial_box mass="0.5" x="0.3" y="0.3" z="0.15">
        <origin xyz="0.15 0 0.05" rpy="0 0 0"/>
    </xacro:inertial_box>

</link>

<!-- LEFT BACK WHEEL -->

<joint name="left_back_wheel_joint" type="continuous">
    <parent link="base_link"/>
    <child link="left_back_wheel_link"/>
    <origin xyz="-0.15 0.12 -0.04" rpy="-${pi/2} 0 0"/>
    <axis xyz="0 0 1"/>
</joint>

<link name="left_back_wheel_link">
    <visual>
        <geometry>
            <cylinder length="0.04" radius="0.05" />
        </geometry>
        <material name="blue"/>
    </visual>
    <collision>
        <geometry>
            <cylinder length="0.04" radius="0.05" />
        </geometry>
        <material name="blue"/>
    </collision>

    <xacro:inertial_cylinder mass="0.1" length="0.04" radius="0.03">
        <origin xyz="-0.15 0.12 -0.04" rpy="-${pi/2} 0 0"/>
    </xacro:inertial_cylinder>

</link>

<!-- RIGHT BACK WHEEL -->

<joint name="right_back_wheel_joint" type="continuous">
    <parent link="base_link"/>
    <child link="right_back_wheel_link"/>
    <origin xyz="-0.15 -0.12 -0.04" rpy="${pi/2} 0 0"/>
    <axis xyz="0 0 -1"/>
</joint>

<link name="right_back_wheel_link">
    <visual>
        <geometry>
            <cylinder length="0.04" radius="0.05" />
        </geometry>
        <material name="blue"/>
    </visual>
    <collision>
        <geometry>
            <cylinder length="0.04" radius="0.05" />
        </geometry>
        <material name="blue"/>
    </collision>

    <xacro:inertial_cylinder mass="0.1" length="0.04" radius="0.03">
        <origin xyz="-0.15 -0.12 -0.04" rpy="${pi/2} 0 0"/>
    </xacro:inertial_cylinder>
    
</link>

<!-- LEFT FRONT WHEEL -->

<joint name="left_front_wheel_joint" type="continuous">
    <parent link="base_link"/>
    <child link="left_front_wheel_link"/>
    <origin xyz="0.15 0.12 -0.04" rpy="-${pi/2} 0 0"/>
    <axis xyz="0 0 1"/>
</joint>

<link name="left_front_wheel_link">
    <visual>
        <geometry>
            <cylinder length="0.04" radius="0.05" />
        </geometry>
        <material name="blue"/>
    </visual>
    <collision>
        <geometry>
            <cylinder length="0.04" radius="0.05" />
        </geometry>
        <material name="blue"/>
    </collision>
    <xacro:inertial_cylinder mass="0.1" length="0.04" radius="0.03">
        <origin xyz="0.15 0.12 -0.04" rpy="-${pi/2} 0 0"/>
    </xacro:inertial_cylinder>

</link>

<!-- RIGHT FRONT WHEEL -->

<joint name="right_front_wheel_joint" type="continuous">
    <parent link="base_link"/>
    <child link="right_front_wheel_link"/>
    <origin xyz="0.15 -0.12 -0.04" rpy="${pi/2} 0 0"/>
    <axis xyz="0 0 -1"/>
</joint>

<link name="right_front_wheel_link">
    <visual>
        <geometry>
            <cylinder length="0.04" radius="0.05" />
        </geometry>
        <material name="blue"/>
    </visual>
    <collision>
        <geometry>
            <cylinder length="0.04" radius="0.05" />
        </geometry>
        <material name="blue"/>
    </collision>

    <xacro:inertial_cylinder mass="0.1" length="0.04" radius="0.03">
        <origin xyz="0.15 -0.12 -0.04" rpy="${pi/2} 0 0"/>
    </xacro:inertial_cylinder>

</link>


</robot>